<?xml version="1.0"?>

<robot name="m0609" xmlns:xacro="http://www.ros.org/wiki/xacro">
		<link name="base_link">
			<inertial>
				<mass value="3.18"/>
				<origin xyz="-2.8e-05   -0.006045    0.038403"/>
				<inertia ixx="0.017789" ixy="-7.4356e-06" ixz="3.0378e-06" iyy="0.011135"
					iyz="-0.00029038"
					izz="0.020054"/>
			</inertial>
			<collision>
				<origin rpy="0 0 0" xyz="0 0 0" />
				<geometry>
					<mesh filename="m0609_collision/MF0609_0_0.dae" scale="0.001 0.001 0.001" />
				</geometry>
			</collision>
			<visual>
				<origin rpy="0 0 0" xyz="0 0 0" />
				<geometry>
					<mesh filename="m0609_white/MF0609_0_0.dae" scale="0.001 0.001 0.001" />
				</geometry>
			</visual>
		</link>
		<link name="base"/>
		<joint name="base_link-base" type="fixed">
			<origin rpy="0 0 0" xyz="0 0 0.450"/>
			<parent link="base_link"/>
			<child link="base"/>
		</joint>
		<!-- joint 1 -->
		<joint name="joint_1" type="revolute">
			<parent link="base_link" />
			<child link="link_1" />
			<origin rpy="0 0 0" xyz="0 0 0.1345" />
			<axis xyz="0 0 1" />
			<limit effort="9600" lower="-6.2832" upper="6.2832" velocity="2.618"/>
			<dynamics friction="0" damping="26.6667" stiffness="266.6667"/>
		</joint>
		<link name="link_1">
			<inertial>
				<mass value="5.02"/>
				<origin xyz="7.2e-05    0.036227   -0.003417"/>
				<inertia ixx="0.026195" ixy="2.3904e-05" ixz="-1.3319e-05" iyy="0.016899"
					iyz="-0.00071987"
					izz="0.022944"/>
			</inertial>
            <collision>
				<origin rpy="0 0 0" xyz="0 0 0" />
				<geometry>
					<mesh filename="m0609_collision/MF0609_1_0.dae" scale="0.001 0.001 0.001" />
				</geometry>
			</collision>
			<visual>
				<origin rpy="0 0 0" xyz="0 0 0" />
				<geometry>
					<mesh filename="m0609_white/MF0609_1_0.dae" scale="0.001 0.001 0.001" />
				</geometry>
			</visual>
		</link>
		<!-- joint2 -->
		<joint name="joint_2" type="revolute">
			<parent link="link_1" />
			<child link="link_2" />
			<origin rpy="0 -1.571 -1.571" xyz="0 0.0062 0" />
			<axis xyz="0 0 1" />
			<limit effort="9600" lower="-6.2832" upper="6.2832" velocity="2.618"/>
			<dynamics friction="0"  damping="26.6667" stiffness="266.6667"/>
		</joint>
		<link name="link_2">
			<inertial>
				<mass value="8.04"/>
				<origin xyz="0.20447     2.6e-05     0.16005"/>
				<inertia ixx="0.026743" ixy="-0.00019461" ixz="-0.00058734" iyy="0.30084"
					iyz="-6.7892e-06"
					izz="0.29898"/>
			</inertial>
            <collision>
				<origin rpy="0 0 0" xyz="0 0 0" />
				<geometry>
					<mesh filename="m0609_collision/MF0609_2_0.dae" scale="0.001 0.001 0.001" />
				</geometry>
			</collision>
			<visual>
				<origin rpy="0 0 0" xyz="0 0 0" />
				<geometry>
					<mesh filename="m0609_white/MF0609_2_0.dae" scale="0.001 0.001 0.001" />
				</geometry>
			</visual>
			<collision>
				<origin rpy="0 0 0" xyz="0 0 0" />
				<geometry>
					<mesh filename="m0609_collision/MF0609_2_1.dae" scale="0.001 0.001 0.001" />
				</geometry>
			</collision>
			<visual>
				<origin rpy="0 0 0" xyz="0 0 0" />
				<geometry>
					<mesh filename="m0609_white/MF0609_2_1.dae" scale="0.001 0.001 0.001" />
				</geometry>
			</visual>
			<collision>
				<origin rpy="0 0 0" xyz="0 0 0" />
				<geometry>
					<mesh filename="m0609_collision/MF0609_2_2.dae" scale="0.001 0.001 0.001" />
				</geometry>
			</collision>
			<visual>
				<origin rpy="0 0 0" xyz="0 0 0" />
				<geometry>
					<mesh filename="m0609_white/MF0609_2_2.dae" scale="0.001 0.001 0.001" />
				</geometry>
			</visual>
		</link>
		<!-- joint3 -->
		<joint name="joint_3" type="revolute">
			<parent link="link_2" />
			<child link="link_3" />
			<origin rpy="0 0 1.571" xyz="0.411 0 0" />
			<axis xyz="0 0 1" />
			<limit effort="5400" lower="-2.618" upper="2.618" velocity="3.1416"/>
			<dynamics friction="0"  damping="15" stiffness="150"/>
		</joint>
		<link name="link_3">
			<inertial>
				<mass value="3.6"/>
				<origin xyz="-2.2e-05   -0.006867    0.043445"/>
				<inertia ixx="0.018342" ixy="1.1302e-05" ixz="-4.5308e-06" iyy="0.018239"
					iyz="-0.00099247"
					izz="0.01326"/>
			</inertial>
			<collision>
				<origin rpy="0 0 0" xyz="0 0 0" />
				<geometry>
					<mesh filename="m0609_collision/MF0609_3_0.dae" scale="0.001 0.001 0.001" />
				</geometry>
			</collision>
			<visual>
				<origin rpy="0 0 0" xyz="0 0 0" />
				<geometry>
					<mesh filename="m0609_white/MF0609_3_0.dae" scale="0.001 0.001 0.001" />
				</geometry>
			</visual>
		</link>
		<!-- joint4 -->
		<joint name="joint_4" type="revolute">
			<parent link="link_3" />
			<child link="link_4" />
			<origin rpy="1.571 0 0" xyz="0 -0.368 0" />
			<axis xyz="0 0 1" />
			<limit effort="2700" lower="-6.2832" upper="6.2832" velocity="3.927"/>
			<dynamics friction="0"  damping="7.5" stiffness="750"/>
		</joint>
		<link name="link_4">
			<inertial>
				<mass value="3.57"/>
				<origin xyz="4e-05    0.097079    -0.10981"/>
				<inertia ixx="0.08035" ixy="-4.6119e-06" ixz="-8.1798e-06" iyy="0.066005"
					iyz="-0.028996"
					izz="0.029763"/>
			</inertial>
            <collision>
				<origin rpy="0 0 0" xyz="0 0 0" />
				<geometry>
					<mesh filename="m0609_collision/MF0609_4_0.dae" scale="0.001 0.001 0.001" />
				</geometry>
			</collision>
			<visual>
				<origin rpy="0 0 0" xyz="0 0 0" />
				<geometry>
					<mesh filename="m0609_white/MF0609_4_0.dae" scale="0.001 0.001 0.001" />
				</geometry>
			</visual>
			<collision>
				<origin rpy="0 0 0" xyz="0 0 0" />
				<geometry>
					<mesh filename="m0609_collision/MF0609_4_1.dae" scale="0.001 0.001 0.001" />
				</geometry>
			</collision>
			<visual>
				<origin rpy="0 0 0" xyz="0 0 0" />
				<geometry>
					<mesh filename="m0609_white/MF0609_4_1.dae" scale="0.001 0.001 0.001" />
				</geometry>
			</visual>
		</link>
		<!-- joint5 -->
		<joint name="joint_5" type="revolute">
			<parent link="link_4" />
			<child link="link_5" />
			<origin rpy="-1.571 0 0" xyz="0 0 0" />
			<axis xyz="0 0 1" />
			<limit effort="2700" lower="-6.2832" upper="6.2832" velocity="3.927"/>
			<dynamics friction="0"   damping="7.5" stiffness="750"/>
		</joint>
		<link name="link_5">
			<inertial>
				<mass value="2.83"/>
				<origin xyz="-6.8e-05    0.003827    0.031969"/>
				<inertia ixx="0.014275" ixy="2.2026e-05" ixz="3.3017e-06" iyy="0.012569"
					iyz="0.00045077"
					izz="0.0085318"/>
			</inertial>
            <collision>
				<origin rpy="0 0 0" xyz="0 0 0" />
				<geometry>
					<mesh filename="m0609_collision/MF0609_5_0.dae" scale="0.001 0.001 0.001" />
				</geometry>
			</collision>
			<visual>
				<origin rpy="0 0 0" xyz="0 0 0" />
				<geometry>
					<mesh filename="m0609_white/MF0609_5_0.dae" scale="0.001 0.001 0.001" />
				</geometry>
			</visual>
		</link>
		<!-- joint6 -->
		<joint name="joint_6" type="revolute">
			<parent link="link_5" />
			<child link="link_6" />
			<origin rpy="1.571 0 0" xyz="0 -0.121 0" />
			<axis xyz="0 0 1" />
			<limit effort="2700" lower="-6.2832" upper="6.2832" velocity="3.927"/>
			<dynamics friction="0"   damping="7.5" stiffness="750"/>
		</joint>
		<link name="link_6">
			<inertial>
				<mass value="1.16"/>
				<origin xyz="-3e-05    -4.5e-05     -0.0539"/>
				<inertia ixx="0.0080226" ixy="1.371e-06" ixz="6.3578e-06" iyy="0.0053992"
					iyz="7.4676e-06"
					izz="0.0053912"/>
			</inertial>
			<collision>
				<origin rpy="0 0 0" xyz="0 0 0" />
				<geometry>
					<mesh filename="m0609_collision/MF0609_6_0.dae" scale="0.001 0.001 0.001" />
				</geometry>
			</collision>
			<visual>
				<origin rpy="0 0 0" xyz="0 0 0" />
				<geometry>
					<mesh filename="m0609_white/MF0609_6_0.dae" scale="0.001 0.001 0.001" />
				</geometry>
			</visual>
		</link>
		<link name="tool0"/>
		<joint name="joint_6-tool0" type="fixed">
			<origin rpy="0 0 0" xyz="0 0 0"/>
			<parent link="link_6"/>
			<child link="tool0"/>
		</joint>


        















        <link name="robotiq_85_base_link">
            <inertial>
            <origin
                xyz="0.00021987 -2.3546E-10 0.030163"
                rpy="0 0 0" />
            <mass
                value="0.30915" />
            <inertia
                ixx="0.00028972"
                ixy="-5.7879E-10"
                ixz="-1.8543E-06"
                iyy="0.00030737"
                iyz="1.682E-12"
                izz="0.00019914" />
            </inertial>
            <visual>
            <origin
                xyz="0 0 0"
                rpy="0 0 0" />
            <geometry>
                <mesh
                filename="package://robotiq_arg85_description/meshes/robotiq_85_base_link_fine.STL" />
            </geometry>
            <material
                name="">
                <color
                rgba="0.1 0.1 0.1 1" />
            </material>
            </visual>
            <collision>
            <origin
                xyz="0 0 0"
                rpy="0 0 0" />
            <geometry>
                <mesh
                filename="package://robotiq_arg85_description/meshes/robotiq_85_base_link_coarse.STL" />
            </geometry>
            </collision>
        </link>
        <link
            name="left_outer_knuckle">
            <inertial>
            <origin
                xyz="0.0178331863169983 3.68915177224286E-11 0.0021442477325704"
                rpy="0 0 0" />
            <mass
                value="0.00684838849434396" />
            <inertia
                ixx="2.66832029033166E-07"
                ixy="1.66142314639824E-15"
                ixz="1.45945633322873E-07"
                iyy="1.3889233257419E-06"
                iyz="2.82951161241588E-15"
                izz="1.26603336914415E-06" />
            </inertial>
            <visual>
            <origin
                xyz="0 0 0"
                rpy="0 0 0" />
            <geometry>
                <mesh
                filename="package://robotiq_arg85_description/meshes/outer_knuckle_fine.STL" />
            </geometry>
            <material
                name="">
                <color
                rgba="0.1 0.1 0.1 1" />
            </material>
            </visual>
            <collision>
            <origin
                xyz="0 0 0"
                rpy="0 0 0" />
            <geometry>
                <mesh
                filename="package://robotiq_arg85_description/meshes/outer_knuckle_coarse.STL" />
            </geometry>
            </collision>
        </link>
        <joint
            name="finger_joint"
            type="revolute">
            <origin
            xyz="0.0306011444260539 0 0.0627920162695395"
            rpy="0 0 0" />
            <parent
            link="robotiq_85_base_link" />
            <child
            link="left_outer_knuckle" />
            <axis
            xyz="0 -1 0" />
            <limit
            lower="0"
            upper="0.725"
            velocity="2.0"
            effort="1000" />
        </joint>
        <link
            name="left_outer_finger">
            <inertial>
            <origin
                xyz="0.00131451599174296 2.88942057994543E-15 0.0215404163180413"
                rpy="0 0 0" />
            <mass
                value="0.0273093985570947" />
            <inertia
                ixx="8.51629628283022E-06"
                ixy="2.58174336207405E-19"
                ixz="3.83829504344079E-07"
                iyy="6.9133328065108E-06"
                iyz="-7.58589926143789E-19"
                izz="2.25006832221981E-06" />
            </inertial>
            <visual>
            <origin
                xyz="0 0 0"
                rpy="0 0 0" />
            <geometry>
                <mesh
                filename="package://robotiq_arg85_description/meshes/outer_finger_fine.STL" />
            </geometry>
            <material
                name="">
                <color
                rgba="0.1 0.1 0.1 1" />
            </material>
            </visual>
            <collision>
            <origin
                xyz="0 0 0"
                rpy="0 0 0" />
            <geometry>
                <mesh
                filename="package://robotiq_arg85_description/meshes/outer_finger_coarse.STL" />
            </geometry>
            </collision>
        </link>
        <joint
            name="left_outer_finger_joint"
            type="fixed">
            <origin
            xyz="0.0316910442266543 0 -0.00193396375724605"
            rpy="0 0 0" />
            <parent
            link="left_outer_knuckle" />
            <child
            link="left_outer_finger" />
            <axis
            xyz="0 -1 0" />
        </joint>
        <link
            name="left_inner_knuckle">
            <inertial>
            <origin
                xyz="0.017097546626628 -3.93808524389535E-10 0.0224918438201868"
                rpy="0 0 0" />
            <mass
                value="0.0110930853895903" />
            <inertia
                ixx="4.23392770691541E-06"
                ixy="5.748978936968E-15"
                ixz="1.78855677119788E-06"
                iyy="3.96548790524392E-06"
                iyz="1.05464666369669E-14"
                izz="3.24068002883007E-06" />
            </inertial>
            <visual>
            <origin
                xyz="0 0 0"
                rpy="0 0 0" />
            <geometry>
                <mesh
                filename="package://robotiq_arg85_description/meshes/inner_knuckle_fine.STL" />
            </geometry>
            <material
                name="">
                <color
                rgba="0.1 0.1 0.1 1" />
            </material>
            </visual>
            <collision>
            <origin
                xyz="0 0 0"
                rpy="0 0 0" />
            <geometry>
                <mesh
                filename="package://robotiq_arg85_description/meshes/inner_knuckle_coarse.STL" />
            </geometry>
            </collision>
        </link>
        <joint
            name="left_inner_knuckle_joint"
            type="revolute">
            <origin
            xyz="0.0127000000001501 0 0.0693074999999639"
            rpy="0 0 0" />
            <parent
            link="robotiq_85_base_link" />
            <child
            link="left_inner_knuckle" />
            <axis
            xyz="0 -1 0" />
            <limit
            lower="0"
            upper="0.8757"
            velocity="2.0"
            effort="1000" />
            <mimic 
            joint="finger_joint"
            multiplier="1"
            offset="0" />
        </joint>
        <link
            name="left_inner_finger">
            <inertial>
            <origin
                xyz="0.0060275613594574 -6.29183141465421E-15 0.00669925693133241"
                rpy="0 0 0" />
            <mass
                value="0.00724255346165745" />
            <inertia
                ixx="1.47824274053603E-06"
                ixy="-3.94884463570303E-19"
                ixz="-3.45268847648622E-07"
                iyy="1.70064480838395E-06"
                iyz="3.5059838910097E-19"
                izz="4.77151336838364E-07" />
            </inertial>
            <visual>
            <origin
                xyz="0 0 0"
                rpy="0 0 0" />
            <geometry>
                <mesh
                filename="package://robotiq_arg85_description/meshes/inner_finger_fine.STL" />
            </geometry>
            <material
                name="">
                <color
                rgba="0.1 0.1 0.1 1" />
            </material>
            </visual>
            <collision>
            <origin
                xyz="0 0 0"
                rpy="0 0 0" />
            <geometry>
                <mesh
                filename="package://robotiq_arg85_description/meshes/inner_finger_coarse.STL" />
            </geometry>
            </collision>
        </link>
        <joint
            name="left_inner_finger_joint"
            type="revolute">
            <origin
            xyz="0.034585310861294 0 0.0454970193817975"
            rpy="0 0 0" />
            <parent
            link="left_inner_knuckle" />
            <child
            link="left_inner_finger" />
            <axis
            xyz="0 -1 0" />
            <limit
            lower="0"
            upper="0.8757"
            velocity="2.0"
            effort="1000" />
            <mimic 
            joint="finger_joint"
            multiplier="-1"
            offset="0" />
        </joint>
        <link
            name="right_inner_knuckle">
            <inertial>
            <origin
                xyz="0.0168606186773776 3.93808471820465E-10 0.0226699950793434"
                rpy="0 0 0" />
            <mass
                value="0.0110930853895903" />
            <inertia
                ixx="4.27134775939882E-06"
                ixy="-8.53568456728898E-15"
                ixz="1.77774229944246E-06"
                iyy="3.96548790524392E-06"
                iyz="-8.45108024914164E-15"
                izz="3.20325997634666E-06" />
            </inertial>
            <visual>
            <origin
                xyz="0 0 0"
                rpy="0 0 0" />
            <geometry>
                <mesh
                filename="package://robotiq_arg85_description/meshes/inner_knuckle_fine.STL" />
            </geometry>
            <material
                name="">
                <color
                rgba="0.1 0.1 0.1 1" />
            </material>
            </visual>
            <collision>
            <origin
                xyz="0 0 0"
                rpy="0 0 0" />
            <geometry>
                <mesh
                filename="package://robotiq_arg85_description/meshes/inner_knuckle_coarse.STL" />
            </geometry>
            </collision>
        </link>
        <joint
            name="right_inner_knuckle_joint"
            type="revolute">
            <origin
            xyz="-0.0126999999998499 0 0.0693075000000361"
            rpy="0 0 3.14159265358979" />
            <parent
            link="robotiq_85_base_link" />
            <child
            link="right_inner_knuckle" />
            <axis
            xyz="0 1 0" />
            <limit
            lower="0"
            upper="0.8757"
            velocity="2.0"
            effort="1000" />
            <mimic 
            joint="finger_joint"
            multiplier="-1"
            offset="0" />
        </joint>
        <link
            name="right_inner_finger">
            <inertial>
            <origin
                xyz="0.00602756228812038 -6.47284509480176E-15 0.00669925609578108"
                rpy="0 0 0" />
            <mass
                value="0.00724255346165744" />
            <inertia
                ixx="1.47824283625957E-06"
                ixy="-3.95952064019123E-19"
                ixz="-3.45268708875543E-07"
                iyy="1.70064480838394E-06"
                iyz="3.55286507960029E-19"
                izz="4.77151241114822E-07" />
            </inertial>
            <visual>
            <origin
                xyz="0 0 0"
                rpy="0 0 0" />
            <geometry>
                <mesh
                filename="package://robotiq_arg85_description/meshes/inner_finger_fine.STL" />
            </geometry>
            <material
                name="">
                <color
                rgba="0.1 0.1 0.1 1" />
            </material>
            </visual>
            <collision>
            <origin
                xyz="0 0 0"
                rpy="0 0 0" />
            <geometry>
                <mesh
                filename="package://robotiq_arg85_description/meshes/inner_finger_coarse.STL" />
            </geometry>
            </collision>
        </link>
        <joint
            name="right_inner_finger_joint"
            type="revolute">
            <origin
            xyz="0.0341060475457406 0 0.0458573878541688"
            rpy="0 0 0" />
            <parent
            link="right_inner_knuckle" />
            <child
            link="right_inner_finger" />
            <axis
            xyz="0 1 0" />
            <limit
            lower="0"
            upper="0.8757"
            velocity="2.0"
            effort="1000" />
            <mimic 
            joint="finger_joint"
            multiplier="1"
            offset="0" />
        </joint>
        <link
            name="right_outer_knuckle">
            <inertial>
            <origin
                xyz="0.0178097074051638 3.60493211424024E-11 0.00233123458346721"
                rpy="0 0 0" />
            <mass
                value="0.00684838849401352" />
            <inertia
                ixx="2.70004361573169E-07"
                ixy="1.59579467624491E-15"
                ixz="1.56396493788199E-07"
                iyy="1.38892332558312E-06"
                iyz="2.82357800318817E-15"
                izz="1.26286103637978E-06" />
            </inertial>
            <visual>
            <origin
                xyz="0 0 0"
                rpy="0 0 0" />
            <geometry>
                <mesh
                filename="package://robotiq_arg85_description/meshes/outer_knuckle_fine.STL" />
            </geometry>
            <material
                name="">
                <color
                rgba="0.1 0.1 0.1 1" />
            </material>
            </visual>
            <collision>
            <origin
                xyz="0 0 0"
                rpy="0 0 0" />
            <geometry>
                <mesh
                filename="package://robotiq_arg85_description/meshes/outer_knuckle_coarse.STL" />
            </geometry>
            </collision>
        </link>
        <joint
            name="right_outer_knuckle_joint"
            type="revolute">
            <origin
            xyz="-0.0306011444258893 0 0.0627920162695395"
            rpy="0 0 3.14159265358979" />
            <parent
            link="robotiq_85_base_link" />
            <child
            link="right_outer_knuckle" />
            <axis
            xyz="0 1 0" />
            <limit
            lower="0"
            upper="0.8757"
            velocity="2.0"
            effort="1000" />
            <mimic 
            joint="finger_joint"
            multiplier="-1"
            offset="0" />
        </joint>
        <link
            name="right_outer_finger">
            <inertial>
            <origin
                xyz="0.00108844269639009 -2.611488350845E-15 0.0215530225245502"
                rpy="0 0 0" />
            <mass
                value="0.0273093985570947" />
            <inertia
                ixx="8.52366028592721E-06"
                ixy="3.41683380899422E-19"
                ixz="3.18003675694284E-07"
                iyy="6.91333280651081E-06"
                iyz="7.37726682706417E-19"
                izz="2.24270431912283E-06" />
            </inertial>
            <visual>
            <origin
                xyz="0 0 0"
                rpy="0 0 0" />
            <geometry>
                <mesh
                filename="package://robotiq_arg85_description/meshes/outer_finger_fine.STL" />
            </geometry>
            <material
                name="">
                <color
                rgba="0.1 0.1 0.1 1" />
            </material>
            </visual>
            <collision>
            <origin
                xyz="0 0 0"
                rpy="0 0 0" />
            <geometry>
                <mesh
                filename="package://robotiq_arg85_description/meshes/outer_finger_coarse.STL" />
            </geometry>
            </collision>
        </link>
        <joint
            name="right_outer_finger_joint"
            type="fixed">
            <origin
            xyz="0.0317095909367246 0 -0.0016013564954687"
            rpy="0 0 0" />
            <parent
            link="right_outer_knuckle" />
            <child
            link="right_outer_finger" />
            <axis
            xyz="0 1 0" />
        </joint>

        <joint name="tool0_to_robotiq_base" type="fixed">
            <parent link="tool0"/>
            <child link="robotiq_85_base_link"/>
            <origin xyz="0 0 0" rpy="0 0 0"/>
        </joint>

</robot>